<?xml version="1.0"?>
<robot xmlns:xacro="http://www.ros.org/wiki/xacro" name="urdf_tutorial">
    <!-- MACROS -->
    <xacro:include filename="macros.xacro"/>
    <xacro:include filename="gazebo.xacro"/>
    
    <!-- COLOR -->
    <material name="white">
        <color rgba="1 1 1 1" />
    </material>

    <material name="blue">
        <color rgba="0 0 1 1" />
    </material>

    <material name="black">
        <color rgba="0 0 0 1" />
    </material>

    <material name="red">
        <color rgba="1 0 0 1" />
    </material>

    <!-- BASE LINK -->
    <link name="base_link">
        <inertial>
            <mass value="1.0" />
            <inertia ixx="0.1" ixy="0.0" ixz="0.0" iyy="0.1" iyz="0.0" izz="0.1" />
        </inertial>
    </link>

    <!-- BODY LINK -->
    <joint name="body_joint" type="fixed">
        <parent link="base_link" />
        <child link="body" />
        <origin xyz="-0.12 0 0" />
    </joint>

    <link name="body">
        <visual>
            <origin xyz="0.1 0 0.03" />
            <geometry>
                <box size="0.2 0.1 0.06" />
            </geometry>
            <material name="white" />
        </visual>
        <collision>
            <origin xyz="0.1 0 0.03" />
            <geometry>
                <box size="0.2 0.1 0.06" />
            </geometry>
        </collision>
    </link>

    <!-- LEFT WHEEL LINK -->
    <joint name="left_wheel_joint" type="continuous">
        <parent link="base_link" />
        <child link="left_wheel" />
        <origin xyz="0 0.065 0" rpy="0 -${pi/2} -${pi/2}" />  <!-- ✅ 바퀴 세우기 -->
        <axis xyz="0 1 0" />  <!-- ✅ 바퀴가 X축을 따라 회전하도록 수정 --> 
    </joint>

    <link name="left_wheel">
        <visual>
            <geometry>
                <cylinder radius="0.03" length="0.02" />
            </geometry>
            <material name="white" />
        </visual>
        <collision>
            <geometry>
                <cylinder radius="0.03" length="0.02" />
            </geometry>
        </collision>
        <inertial>
            <mass value="0.5"/>
            <inertia ixx="0.01" ixy="0.0" ixz="0.0"
                     iyy="0.01" iyz="0.0"
                     izz="0.02"/>
        </inertial>
    </link>

    <!-- RIGHT WHEEL LINK -->
    <joint name="right_wheel_joint" type="continuous">
        <parent link="base_link" />
        <child link="right_wheel" />
        <origin xyz="0 -0.065 0" rpy="0 -${pi/2} -${pi/2}" />
        <axis xyz="0 1 0" />
    </joint>

    <link name="right_wheel">
        <visual>
            <geometry>
                <cylinder radius="0.03" length="0.03" />
            </geometry>
            <material name="white" />
        </visual>
        <collision>
            <geometry>
                <cylinder radius="0.03" length="0.03" />
            </geometry>
        </collision>
        <inertial>
            <mass value="0.5"/>
            <inertia ixx="0.01" ixy="0.0" ixz="0.0"
                     iyy="0.01" iyz="0.0"
                     izz="0.02"/>
        </inertial>
    </link>

    <!-- CASTER WHEEL LINK -->
    <joint name="caster_wheel_joint" type="fixed">
        <parent link="body" />
        <child link="caster_wheel" />
        <origin xyz="0.03 0 0" />
    </joint>

    <link name="caster_wheel">
        <visual>
            <geometry>
                <sphere radius="0.03" />
            </geometry>
            <material name="black" />
        </visual>
        <collision>
            <geometry>
                <sphere radius="0.03" />
            </geometry>
        </collision>
    </link>

    <!-- CAMERA -->
    <joint name="camera_joint" type="fixed">
        <parent link="body" />
        <child link="camera_link" />
        <origin xyz="0.20 0.0 0.03" rpy="0 0 0" />
    </joint>

    <link name="camera_link">
        <visual>
            <geometry>
                <box size="0.01 0.03 0.03" />
            </geometry>
            <material name="red" />
        </visual>
        <collision>
            <geometry>
                <box size="0.01 0.03 0.03" />
            </geometry>
        </collision>
    </link>

</robot>